<?xml version="1.0"?>
<robot name="m1013">

  <link name="base_0">
    <inertial>
      <mass value="3.722"/>
      <origin xyz="-1.2e-05 -6e-05 0.050723"/>
      <inertia ixx="0.011" ixy="-7.19e-06" ixz="-1.94e-06"
               iyy="0.011" iyz="4.9e-06" izz="0.014"/>
    </inertial>
    <visual>
      <geometry>
        <mesh filename="file:///home/protima/ros2_internship_project/software-assignment-pr342-main/assessment_ws/src/my_doosan_pkg/description/meshes/m1013_white/MF1013_0_0.dae"/>
      </geometry>
    </visual>
  </link>

  <joint name="joint1" type="revolute">
    <parent link="base_0"/>
    <child link="link1"/>
    <origin xyz="0 0 0.1525"/>
    <axis xyz="0 0 1"/>
    <limit effort="30" lower="-2.617" upper="2.617" velocity="1.571"/>
  </joint>

  <link name="link1">
    <inertial>
      <mass value="7.446"/>
    </inertial>
    <visual>
      <geometry>
        <mesh filename="file:///home/protima/ros2_internship_project/software-assignment-pr342-main/assessment_ws/src/my_doosan_pkg/description/meshes/m1013_white/MF1013_1_0.dae"/>
      </geometry>
    </visual>
  </link>

  <joint name="joint2" type="revolute">
    <parent link="link1"/>
    <child link="link2"/>
    <origin xyz="0 0.0345 0"/>
    <axis xyz="0 0 1"/>
    <limit effort="30" lower="-2.617" upper="2.617" velocity="1.571"/>
  </joint>

  <link name="link2">
    <inertial>
      <mass value="10.569"/>
    </inertial>

    <visual><geometry>
      <mesh filename="file:///home/protima/ros2_internship_project/software-assignment-pr342-main/assessment_ws/src/my_doosan_pkg/description/meshes/m1013_white/MF1013_2_0.dae"/>
    </geometry></visual>

    <visual><geometry>
      <mesh filename="file:///home/protima/ros2_internship_project/software-assignment-pr342-main/assessment_ws/src/my_doosan_pkg/description/meshes/m1013_white/MF1013_2_1.dae"/>
    </geometry></visual>

    <visual><geometry>
      <mesh filename="file:///home/protima/ros2_internship_project/software-assignment-pr342-main/assessment_ws/src/my_doosan_pkg/description/meshes/m1013_white/MF1013_2_2.dae"/>
    </geometry></visual>
  </link>

  <joint name="joint3" type="revolute">
    <parent link="link2"/>
    <child link="link3"/>
    <origin xyz="0.62 0 0"/>
    <axis xyz="0 0 1"/>
    <limit effort="30" lower="-2.617" upper="2.617" velocity="1.571"/>
  </joint>

  <link name="link3">
    <visual>
      <geometry>
        <mesh filename="file:///home/protima/ros2_internship_project/software-assignment-pr342-main/assessment_ws/src/my_doosan_pkg/description/meshes/m1013_white/MF1013_3_0.dae"/>
      </geometry>
    </visual>
  </link>

  <joint name="joint4" type="revolute">
    <parent link="link3"/>
    <child link="link4"/>
    <origin xyz="0 -0.559 0"/>
    <axis xyz="0 0 1"/>
  </joint>

  <link name="link4">
    <visual>
      <geometry>
        <mesh filename="file:///home/protima/ros2_internship_project/software-assignment-pr342-main/assessment_ws/src/my_doosan_pkg/description/meshes/m1013_white/MF1013_4_0.dae"/>
      </geometry>
    </visual>
    <visual>
      <geometry>
        <mesh filename="file:///home/protima/ros2_internship_project/software-assignment-pr342-main/assessment_ws/src/my_doosan_pkg/description/meshes/m1013_white/MF1013_4_1.dae"/>
      </geometry>
    </visual>
  </link>

  <joint name="joint5" type="revolute">
    <parent link="link4"/>
    <child link="link5"/>
  </joint>

  <link name="link5">
    <visual>
      <geometry>
        <mesh filename="file:///home/protima/ros2_internship_project/software-assignment-pr342-main/assessment_ws/src/my_doosan_pkg/description/meshes/m1013_white/MF1013_5_0.dae"/>
      </geometry>
    </visual>
  </link>

  <joint name="joint6" type="revolute">
    <parent link="link5"/>
    <child link="link6"/>
  </joint>

  <link name="link6">
    <visual>
      <geometry>
        <mesh filename="file:///home/protima/ros2_internship_project/software-assignment-pr342-main/assessment_ws/src/my_doosan_pkg/description/meshes/m1013_white/MF1013_6_0.dae"/>
      </geometry>
    </visual>
  </link>

</robot>

